Workbook

Sheet Lisez-moi
B1: Calculateur d'indicateurs d'alarmes
B2: alarm-rationalization-field-guide · outil libre sous licence CC BY 4.0 · Julien Sisavath (juliensisavath.com)
B4: À quoi sert ce classeur : mesurer la charge d'alarmes d'un poste opérateur à partir d'un export de journal d'alarmes, et la comparer aux valeurs de référence publiées pour ISA-18.2 / IEC 62682 et EEMUA 191. En 15 minutes, vous savez si votre système d'alarmes aide vos opérateurs ou s'il les noie.
B6: Mode d'emploi
B7: 1. Exportez le journal d'alarmes de votre supervision (SCADA, GTC, IHM d'automate) sur 1 à 4 semaines d'exploitation normale.
B8: 2. Mettez-le au format « une ligne par alarme » : horodatage d'activation, horodatage de retour (vide si l'alarme est encore active), tag, description, priorité, zone. Voir methodology/02-collecte-journal.md si votre export sépare activation, acquittement et retour.
B9: 3. Onglet Journal : effacez les données d'exemple dans les colonnes A à F uniquement, puis collez les vôtres à partir de la ligne 2. Ne modifiez pas les colonnes G à U (calculées).
B10: 4. Vérifiez que les dates sont reconnues comme des dates (alignées à droite). Format conseillé : AAAA-MM-JJ hh:mm:ss.
B11: 5. Onglet Paramètres : indiquez le nombre de postes opérateur et vos libellés de priorité. La période est déduite du journal si vous laissez les dates vides.
B12: 6. Lisez les onglets Indicateurs, Top 10 et Pires périodes. Les colonnes « Cible » et « Limite » de l'onglet Indicateurs sont modifiables.
B14: Code couleur
B15: Texte bleu sur fond jaune clair : cellules à saisir ou à ajuster. Texte noir : formules. Texte vert : valeurs reprises d'un autre onglet.
... B32: Le journal pré-chargé est entièrement fictif : 7 jours d'alarmes d'une laiterie imaginaire, LactoDémo SA. Aucune donnée réelle. L'analyse commentée se trouve dans examples/analyse-site-fictif.md.

Sheet Indicateurs
A1: Indicateurs de performance du système d'alarmes
A2: ="Période analysée : du "&TEXT(Debut,"yyyy-mm-dd hh:mm")&" au "&TEXT(Fin,"yyyy-mm-dd hh:mm")&" ("&TEXT(Jours,"0.0")&" jours), "&NbPostes&" poste(s) opérateur" -> Période analysée : du 2026-03-02 00:00 au 2026-03-09 00:00 (7.0 jours), 1 poste(s) opérateur
A4: Indicateur | B4: Valeur | C4: Cible | D4: Limite | E4: Statut | F4: Référence et lecture
A5: Alarmes annoncées sur la période | B5: =COUNTIF(Journal!$G:$G,1) -> 1336 | F5: Activations dans la période. Base de tous les ratios.
A6: Tags distincts ayant alarmé | B6: =COUNT(Journal!$P:$P) -> 33 | F6: Nombre de points différents.
A7: Moyenne d'alarmes par jour et par poste | B7: =IF(Jours>0,B5/Jours/NbPostes,"") -> 190.85714 | C7: 150 | D7: 300 | E7: =IF(B7="","",IF(B7<=C7,"Conforme",IF(B7<=D7,"À surveiller","Hors cible"))) -> À surveiller | F7: ISA-18.2 : env. 150/jour très probablement acceptable, env. 300/jour maximum gérable.
A8: Moyenne d'alarmes par heure et par poste | B8: =IF(Jours>0,B5/(Jours*24)/NbPostes,"") -> 7.952381 | C8: 6 | D8: 12 | E8: =IF(B8="","",IF(B8<=C8,"Conforme",IF(B8<=D8,"À surveiller","Hors cible"))) -> À surveiller | F8: ISA-18.2 : env. 6/h acceptable, env. 12/h maximum gérable.
A9: Moyenne d'alarmes par 10 minutes et par poste | B9: =IF(Jours>0,B5/(Jours*144)/NbPostes,"") -> 1.3253968 | C9: 1 | D9: 2 | E9: =IF(B9="","",IF(B9<=C9,"Conforme",IF(B9<=D9,"À surveiller","Hors cible"))) -> À surveiller | F9: ISA-18.2 et EEMUA 191 : env. 1 alarme par 10 min en régime établi.
A10: Maximum d'alarmes dans une fenêtre de 10 minutes | B10: =MAX(Journal!$N:$N) -> 44 | C10: 10 | D10: 10 | E10: =IF(B10="","",IF(B10<=C10,"Conforme",IF(B10<=D10,"À surveiller","Hors cible"))) -> Hors cible | F10: ISA-18.2 : 10 ou moins. Au-delà, l'opérateur ne peut plus traiter chaque alarme. Voir onglet Pires périodes.
A11: Part des fenêtres de 10 min en avalanche | B11: =IF(Jours>0,COUNTIF(Journal!$N:$N,">"&SeuilAvalanche)/(Jours*144),"") -> 0.011904762 | C11: 0.01 | D11: 0.01 | E11: =IF(B11="","",IF(B11<=C11,"Conforme",IF(B11<=D11,"À surveiller","Hors cible"))) -> Hors cible | F11: ISA-18.2 : moins de 1 % du temps en avalanche (approximation par fenêtres fixes).
A12: Part des heures avec plus de 30 alarmes | B12: =IF(Jours>0,COUNTIF(Journal!$O:$O,">"&SeuilHeure)/(Jours*24),"") -> 0.011904762 | C12: 0.01 | D12: 0.01 | E12: =IF(B12="","",IF(B12<=C12,"Conforme",IF(B12<=D12,"À surveiller","Hors cible"))) -> Hors cible | F12: ISA-18.2 : moins de 1 % des heures.
A13: Part des activations dues au top 10 | B13: =IF(B5=0,"",'Top 10'!F16/B5) -> 0.87050898 | C13: 0.05 | D13: 0.05 | E13: =IF(B13="","",IF(B13<=C13,"Conforme",IF(B13<=D13,"À surveiller","Hors cible"))) -> Hors cible | F13: ISA-18.2 : 1 à 5 % au maximum, avec plan d'action. Sur un petit système (moins d'une centaine de tags), ce ratio reste élevé par construction : regardez surtout le volume du top 10.
A14: Tags intermittents (chattering) | B14: =SUM(Journal!$Q:$Q) -> 6 | C14: 0 | D14: 0 | E14: =IF(B14="","",IF(B14<=C14,"Conforme",IF(B14<=D14,"À surveiller","Hors cible"))) -> Hors cible | F14: Cible : aucun, plan d'action pour chacun. Correction typique : bande morte ou temporisation.
A15: Tags fugitifs (fleeting) | B15: =SUM(Journal!$S:$S) -> 7 | C15: 0 | D15: 0 | E15: =IF(B15="","",IF(B15<=C15,"Conforme",IF(B15<=D15,"À surveiller","Hors cible"))) -> Hors cible | F15: Cible : aucun. Retour en moins de 5 s, impossible d'agir.
A16: Tags figés (actifs plus de 24 h) | B16: =SUM(Journal!$R:$R) -> 2 | C16: 0 | D16: 4 | E16: =IF(B16="","",IF(B16<=C16,"Conforme",IF(B16<=D16,"À surveiller","Hors cible"))) -> À surveiller | F16: ISA-18.2 : moins de 5 par jour, avec plan d'action pour chacun. Cible 0 = choix de l'auteur*.
A17: Part des alarmes en priorité haute | B17: =IF(B5=0,"",COUNTIFS(Journal!$G:$G,1,Journal!$E:$E,PrioHaute)/B5) -> 0.35928144 | C17: 0.05 | D17: 0.1 | E17: =IF(B17="","",IF(B17<=C17,"Conforme",IF(B17<=D17,"À surveiller","Hors cible"))) -> Hors cible | F17: Répartition de référence env. 80 % basse / 15 % moyenne / 5 % haute. Limite = choix de l'auteur*.
A18: Part des alarmes en priorité moyenne | B18: =IF(B5=0,"",COUNTIFS(Journal!$G:$G,1,Journal!$E:$E,PrioMoyenne)/B5) -> 0.28218563 | C18: 0.15 | D18: 0.25 | E18: =IF(B18="","",IF(B18<=C18,"Conforme",IF(B18<=D18,"À surveiller","Hors cible"))) -> Hors cible | F18: Idem. Limite = choix de l'auteur*.
A19: Part des alarmes en priorité basse | B19: =IF(B5=0,"",COUNTIFS(Journal!$G:$G,1,Journal!$E:$E,PrioBasse)/B5) -> 0.35853293 | C19: 0.8 | D19: 0.7 | E19: =IF(B19="","",IF(B19>=C19,"Conforme",IF(B19>=D19,"À surveiller","Hors cible"))) -> Hors cible | F19: Idem, ici c'est un minimum. Limite = choix de l'auteur*.
A20: Activations d'alarmes intermittentes | B20: =SUM(Journal!$K:$K) -> 416 | F20: Information : volume généré par les répétitions rapprochées.
A21: Alarmes encore actives en fin de période | B21: =SUM(Journal!$U:$U) -> 1 | F21: Information : alarmes permanentes à l'écran à la fin de l'export.
A23: Valeurs de référence indicatives, telles que publiées pour ISA-18.2 / IEC 62682 et EEMUA 191. * Seuils intermédiaires choisis par l'auteur, à remplacer par ceux de la philosophie d'alarme du site. Les cellules Cible et Limite sont modifiables.
A26: Alarmes par jour (par poste)
A27: Jour | B27: Alarmes | C27: Statut
A28: =IF(Debut+0<Fin,Debut+0,"") -> 46083 | B28: =IF(A28="","",COUNTIFS(Journal!$G:$G,1,Journal!$A:$A,">="&A28,Journal!$A:$A,"<"&(A28+1))/NbPostes) -> 213 | C28: =IF(B28="","",IF(B28<=$C$7,"Conforme",IF(B28<=$D$7,"À surveiller","Hors cible"))) -> À surveiller
A29: =IF(Debut+1<Fin,Debut+1,"") -> 46084 | B29: =IF(A29="","",COUNTIFS(Journal!$G:$G,1,Journal!$A:$A,">="&A29,Journal!$A:$A,"<"&(A29+1))/NbPostes) -> 187 | C29: =IF(B29="","",IF(B29<=$C$7,"Conforme",IF(B29<=$D$7,"À surveiller","Hors cible"))) -> À surveiller
A30: =IF(Debut+2<Fin,Debut+2,"") -> 46085 | B30: =IF(A30="","",COUNTIFS(Journal!$G:$G,1,Journal!$A:$A,">="&A30,Journal!$A:$A,"<"&(A30+1))/NbPostes) -> 260 | C30: =IF(B30="","",IF(B30<=$C$7,"Conforme",IF(B30<=$D$7,"À surveiller","Hors cible"))) -> À surveiller
A31: =IF(Debut+3<Fin,Debut+3,"") -> 46086 | B31: =IF(A31="","",COUNTIFS(Journal!$G:$G,1,Journal!$A:$A,">="&A31,Journal!$A:$A,"<"&(A31+1))/NbPostes) -> 173 | C31: =IF(B31="","",IF(B31<=$C$7,"Conforme",IF(B31<=$D$7,"À surveiller","Hors cible"))) -> À surveiller
A32: =IF(Debut+4<Fin,Debut+4,"") -> 46087 | B32: =IF(A32="","",COUNTIFS(Journal!$G:$G,1,Journal!$A:$A,">="&A32,Journal!$A:$A,"<"&(A32+1))/NbPostes) -> 188 | C32: =IF(B32="","",IF(B32<=$C$7,"Conforme",IF(B32<=$D$7,"À surveiller","Hors cible"))) -> À surveiller
A33: =IF(Debut+5<Fin,Debut+5,"") -> 46088 | B33: =IF(A33="","",COUNTIFS(Journal!$G:$G,1,Journal!$A:$A,">="&A33,Journal!$A:$A,"<"&(A33+1))/NbPostes) -> 250 | C33: =IF(B33="","",IF(B33<=$C$7,"Conforme",IF(B33<=$D$7,"À surveiller","Hors cible"))) -> À surveiller
A34: =IF(Debut+6<Fin,Debut+6,"") -> 46089 | B34: =IF(A34="","",COUNTIFS(Journal!$G:$G,1,Journal!$A:$A,">="&A34,Journal!$A:$A,"<"&(A34+1))/NbPostes) -> 65 | C34: =IF(B34="","",IF(B34<=$C$7,"Conforme",IF(B34<=$D$7,"À surveiller","Hors cible"))) -> Conforme
A35: =IF(Debut+7<Fin,Debut+7,"") | B35: =IF(A35="","",COUNTIFS(Journal!$G:$G,1,Journal!$A:$A,">="&A35,Journal!$A:$A,"<"&(A35+1))/NbPostes) | C35: =IF(B35="","",IF(B35<=$C$7,"Conforme",IF(B35<=$D$7,"À surveiller","Hors cible")))
A36: =IF(Debut+8<Fin,Debut+8,"") | B36: =IF(A36="","",COUNTIFS(Journal!$G:$G,1,Journal!$A:$A,">="&A36,Journal!$A:$A,"<"&(A36+1))/NbPostes) | C36: =IF(B36="","",IF(B36<=$C$7,"Conforme",IF(B36<=$D$7,"À surveiller","Hors cible")))
A37: =IF(Debut+9<Fin,Debut+9,"") | B37: =IF(A37="","",COUNTIFS(Journal!$G:$G,1,Journal!$A:$A,">="&A37,Journal!$A:$A,"<"&(A37+1))/NbPostes) | C37: =IF(B37="","",IF(B37<=$C$7,"Conforme",IF(B37<=$D$7,"À surveiller","Hors cible")))
A38: =IF(Debut+10<Fin,Debut+10,"") | B38: =IF(A38="","",COUNTIFS(Journal!$G:$G,1,Journal!$A:$A,">="&A38,Journal!$A:$A,"<"&(A38+1))/NbPostes) | C38: =IF(B38="","",IF(B38<=$C$7,"Conforme",IF(B38<=$D$7,"À surveiller","Hors cible")))
A39: =IF(Debut+11<Fin,Debut+11,"") | B39: =IF(A39="","",COUNTIFS(Journal!$G:$G,1,Journal!$A:$A,">="&A39,Journal!$A:$A,"<"&(A39+1))/NbPostes) | C39: =IF(B39="","",IF(B39<=$C$7,"Conforme",IF(B39<=$D$7,"À surveiller","Hors cible")))
A40: =IF(Debut+12<Fin,Debut+12,"") | B40: =IF(A40="","",COUNTIFS(Journal!$G:$G,1,Journal!$A:$A,">="&A40,Journal!$A:$A,"<"&(A40+1))/NbPostes) | C40: =IF(B40="","",IF(B40<=$C$7,"Conforme",IF(B40<=$D$7,"À surveiller","Hors cible")))
A41: =IF(Debut+13<Fin,Debut+13,"") | B41: =IF(A41="","",COUNTIFS(Journal!$G:$G,1,Journal!$A:$A,">="&A41,Journal!$A:$A,"<"&(A41+1))/NbPostes) | C41: =IF(B41="","",IF(B41<=$C$7,"Conforme",IF(B41<=$D$7,"À surveiller","Hors cible")))
A42: =IF(Debut+14<Fin,Debut+14,"") | B42: =IF(A42="","",COUNTIFS(Journal!$G:$G,1,Journal!$A:$A,">="&A42,Journal!$A:$A,"<"&(A42+1))/NbPostes) | C42: =IF(B42="","",IF(B42<=$C$7,"Conforme",IF(B42<=$D$7,"À surveiller","Hors cible")))
A43: =IF(Debut+15<Fin,Debut+15,"") | B43: =IF(A43="","",COUNTIFS(Journal!$G:$G,1,Journal!$A:$A,">="&A43,Journal!$A:$A,"<"&(A43+1))/NbPostes) | C43: =IF(B43="","",IF(B43<=$C$7,"Conforme",IF(B43<=$D$7,"À surveiller","Hors cible")))
A44: =IF(Debut+16<Fin,Debut+16,"") | B44: =IF(A44="","",COUNTIFS(Journal!$G:$G,1,Journal!$A:$A,">="&A44,Journal!$A:$A,"<"&(A44+1))/NbPostes) | C44: =IF(B44="","",IF(B44<=$C$7,"Conforme",IF(B44<=$D$7,"À surveiller","Hors cible")))
...

Sheet Top 10
A1: Top 10 des alarmes les plus fréquentes
A2: Les dix tags qui génèrent le plus d'activations sur la période. C'est presque toujours ici que se trouve le gain le plus rapide.
A4: Rang | B4: Tag | C4: Description | D4: Priorité | E4: Zone | F4: Occurrences | G4: % du total | H4: % cumulé | I4: Intermittente | J4: Fugitive | K4: Figée | L4: Piste de traitement (saisie libre) | M4: clé
A5: 1 | B5: =IF(M5="","",INDEX(Journal!$C:$C,MATCH(M5,Journal!$P:$P,0))) -> FR02_TT01_H | C5: =IF(M5="","",INDEX(Journal!$D:$D,MATCH(M5,Journal!$P:$P,0))) -> Chambre froide 2 - température haute | D5: =IF(M5="","",INDEX(Journal!$E:$E,MATCH(M5,Journal!$P:$P,0))) -> Haute | E5: =IF(M5="","",INDEX(Journal!$F:$F,MATCH(M5,Journal!$P:$P,0))) -> Froid | F5: =IF(M5="","",INT(M5)) -> 431 | G5: =IF(F5="","",F5/Indicateurs!$B$5) -> 0.32260479 | H5: =IF(F5="","",SUM($F$5:F5)/Indicateurs!$B$5) -> 0.32260479 | I5: =IF(B5="","",IF(COUNTIFS(Journal!$C:$C,B5,Journal!$K:$K,1)>0,"Oui","Non")) -> Oui | J5: =IF(B5="","",IF(COUNTIFS(Journal!$C:$C,B5,Journal!$L:$L,1)>0,"Oui","Non")) -> Oui | K5: =IF(B5="","",IF(COUNTIFS(Journal!$C:$C,B5,Journal!$M:$M,1)>0,"Oui","Non")) -> Non | M5: =IFERROR(LARGE(Journal!$P:$P,A5),"") -> 431
A6: 2 | B6: =IF(M6="","",INDEX(Journal!$C:$C,MATCH(M6,Journal!$P:$P,0))) -> AIR_PT01_L | C6: =IF(M6="","",INDEX(Journal!$D:$D,MATCH(M6,Journal!$P:$P,0))) -> Air comprimé - pression réseau basse | D6: =IF(M6="","",INDEX(Journal!$E:$E,MATCH(M6,Journal!$P:$P,0))) -> Moyenne | E6: =IF(M6="","",INDEX(Journal!$F:$F,MATCH(M6,Journal!$P:$P,0))) -> Utilités | F6: =IF(M6="","",INT(M6)) -> 178 | G6: =IF(F6="","",F6/Indicateurs!$B$5) -> 0.13323353 | H6: =IF(F6="","",SUM($F$5:F6)/Indicateurs!$B$5) -> 0.45583832 | I6: =IF(B6="","",IF(COUNTIFS(Journal!$C:$C,B6,Journal!$K:$K,1)>0,"Oui","Non")) -> Oui | J6: =IF(B6="","",IF(COUNTIFS(Journal!$C:$C,B6,Journal!$L:$L,1)>0,"Oui","Non")) -> Oui | K6: =IF(B6="","",IF(COUNTIFS(Journal!$C:$C,B6,Journal!$M:$M,1)>0,"Oui","Non")) -> Non | M6: =IFERROR(LARGE(Journal!$P:$P,A6),"") -> 178
A7: 3 | B7: =IF(M7="","",INDEX(Journal!$C:$C,MATCH(M7,Journal!$P:$P,0))) -> CND_ST04_ARR | C7: =IF(M7="","",INDEX(Journal!$D:$D,MATCH(M7,Journal!$P:$P,0))) -> Conditionneuse 4 - machine à l'arrêt | D7: =IF(M7="","",INDEX(Journal!$E:$E,MATCH(M7,Journal!$P:$P,0))) -> Basse | E7: =IF(M7="","",INDEX(Journal!$F:$F,MATCH(M7,Journal!$P:$P,0))) -> Conditionnement | F7: =IF(M7="","",INT(M7)) -> 162 | G7: =IF(F7="","",F7/Indicateurs!$B$5) -> 0.12125749 | H7: =IF(F7="","",SUM($F$5:F7)/Indicateurs!$B$5) -> 0.57709581 | I7: =IF(B7="","",IF(COUNTIFS(Journal!$C:$C,B7,Journal!$K:$K,1)>0,"Oui","Non")) -> Non | J7: =IF(B7="","",IF(COUNTIFS(Journal!$C:$C,B7,Journal!$L:$L,1)>0,"Oui","Non")) -> Non | K7: =IF(B7="","",IF(COUNTIFS(Journal!$C:$C,B7,Journal!$M:$M,1)>0,"Oui","Non")) -> Non | M7: =IFERROR(LARGE(Journal!$P:$P,A7),"") -> 162.00001
A8: 4 | B8: =IF(M8="","",INDEX(Journal!$C:$C,MATCH(M8,Journal!$P:$P,0))) -> CND_ST02_ARR | C8: =IF(M8="","",INDEX(Journal!$D:$D,MATCH(M8,Journal!$P:$P,0))) -> Conditionneuse 2 - machine à l'arrêt | D8: =IF(M8="","",INDEX(Journal!$E:$E,MATCH(M8,Journal!$P:$P,0))) -> Basse | E8: =IF(M8="","",INDEX(Journal!$F:$F,MATCH(M8,Journal!$P:$P,0))) -> Conditionnement | F8: =IF(M8="","",INT(M8)) -> 92 | G8: =IF(F8="","",F8/Indicateurs!$B$5) -> 0.068862275 | H8: =IF(F8="","",SUM($F$5:F8)/Indicateurs!$B$5) -> 0.64595808 | I8: =IF(B8="","",IF(COUNTIFS(Journal!$C:$C,B8,Journal!$K:$K,1)>0,"Oui","Non")) -> Non | J8: =IF(B8="","",IF(COUNTIFS(Journal!$C:$C,B8,Journal!$L:$L,1)>0,"Oui","Non")) -> Non | K8: =IF(B8="","",IF(COUNTIFS(Journal!$C:$C,B8,Journal!$M:$M,1)>0,"Oui","Non")) -> Non | M8: =IFERROR(LARGE(Journal!$P:$P,A8),"") -> 92.000006
A9: 5 | B9: =IF(M9="","",INDEX(Journal!$C:$C,MATCH(M9,Journal!$P:$P,0))) -> FR01_PORTE | C9: =IF(M9="","",INDEX(Journal!$D:$D,MATCH(M9,Journal!$P:$P,0))) -> Chambre froide 1 - porte ouverte > 5 min | D9: =IF(M9="","",INDEX(Journal!$E:$E,MATCH(M9,Journal!$P:$P,0))) -> Moyenne | E9: =IF(M9="","",INDEX(Journal!$F:$F,MATCH(M9,Journal!$P:$P,0))) -> Froid | F9: =IF(M9="","",INT(M9)) -> 73 | G9: =IF(F9="","",F9/Indicateurs!$B$5) -> 0.054640719 | H9: =IF(F9="","",SUM($F$5:F9)/Indicateurs!$B$5) -> 0.7005988 | I9: =IF(B9="","",IF(COUNTIFS(Journal!$C:$C,B9,Journal!$K:$K,1)>0,"Oui","Non")) -> Non | J9: =IF(B9="","",IF(COUNTIFS(Journal!$C:$C,B9,Journal!$L:$L,1)>0,"Oui","Non")) -> Non | K9: =IF(B9="","",IF(COUNTIFS(Journal!$C:$C,B9,Journal!$M:$M,1)>0,"Oui","Non")) -> Non | M9: =IFERROR(LARGE(Journal!$P:$P,A9),"") -> 73.000005
A10: 6 | B10: =IF(M10="","",INDEX(Journal!$C:$C,MATCH(M10,Journal!$P:$P,0))) -> NEP_TT02_L | C10: =IF(M10="","",INDEX(Journal!$D:$D,MATCH(M10,Journal!$P:$P,0))) -> NEP - température retour basse | D10: =IF(M10="","",INDEX(Journal!$E:$E,MATCH(M10,Journal!$P:$P,0))) -> Basse | E10: =IF(M10="","",INDEX(Journal!$F:$F,MATCH(M10,Journal!$P:$P,0))) -> NEP | F10: =IF(M10="","",INT(M10)) -> 55 | G10: =IF(F10="","",F10/Indicateurs!$B$5) -> 0.041167665 | H10: =IF(F10="","",SUM($F$5:F10)/Indicateurs!$B$5) -> 0.74176647 | I10: =IF(B10="","",IF(COUNTIFS(Journal!$C:$C,B10,Journal!$K:$K,1)>0,"Oui","Non")) -> Oui | J10: =IF(B10="","",IF(COUNTIFS(Journal!$C:$C,B10,Journal!$L:$L,1)>0,"Oui","Non")) -> Oui | K10: =IF(B10="","",IF(COUNTIFS(Journal!$C:$C,B10,Journal!$M:$M,1)>0,"Oui","Non")) -> Non | M10: =IFERROR(LARGE(Journal!$P:$P,A10),"") -> 55.000004
A11: 7 | B11: =IF(M11="","",INDEX(Journal!$C:$C,MATCH(M11,Journal!$P:$P,0))) -> CND_ST01_ARR | C11: =IF(M11="","",INDEX(Journal!$D:$D,MATCH(M11,Journal!$P:$P,0))) -> Conditionneuse 1 - machine à l'arrêt | D11: =IF(M11="","",INDEX(Journal!$E:$E,MATCH(M11,Journal!$P:$P,0))) -> Basse | E11: =IF(M11="","",INDEX(Journal!$F:$F,MATCH(M11,Journal!$P:$P,0))) -> Conditionnement | F11: =IF(M11="","",INT(M11)) -> 54 | G11: =IF(F11="","",F11/Indicateurs!$B$5) -> 0.040419162 | H11: =IF(F11="","",SUM($F$5:F11)/Indicateurs!$B$5) -> 0.78218563 | I11: =IF(B11="","",IF(COUNTIFS(Journal!$C:$C,B11,Journal!$K:$K,1)>0,"Oui","Non")) -> Non | J11: =IF(B11="","",IF(COUNTIFS(Journal!$C:$C,B11,Journal!$L:$L,1)>0,"Oui","Non")) -> Non | K11: =IF(B11="","",IF(COUNTIFS(Journal!$C:$C,B11,Journal!$M:$M,1)>0,"Oui","Non")) -> Non | M11: =IFERROR(LARGE(Journal!$P:$P,A11),"") -> 54.000008
A12: 8 | B12: =IF(M12="","",INDEX(Journal!$C:$C,MATCH(M12,Journal!$P:$P,0))) -> REC_FT01_DEV | C12: =IF(M12="","",INDEX(Journal!$D:$D,MATCH(M12,Journal!$P:$P,0))) -> Réception - écart débitmètre / bon de livraison | D12: =IF(M12="","",INDEX(Journal!$E:$E,MATCH(M12,Journal!$P:$P,0))) -> Basse | E12: =IF(M12="","",INDEX(Journal!$F:$F,MATCH(M12,Journal!$P:$P,0))) -> Réception | F12: =IF(M12="","",INT(M12)) -> 52 | G12: =IF(F12="","",F12/Indicateurs!$B$5) -> 0.038922156 | H12: =IF(F12="","",SUM($F$5:F12)/Indicateurs!$B$5) -> 0.82110778 | I12: =IF(B12="","",IF(COUNTIFS(Journal!$C:$C,B12,Journal!$K:$K,1)>0,"Oui","Non")) -> Non | J12: =IF(B12="","",IF(COUNTIFS(Journal!$C:$C,B12,Journal!$L:$L,1)>0,"Oui","Non")) -> Non | K12: =IF(B12="","",IF(COUNTIFS(Journal!$C:$C,B12,Journal!$M:$M,1)>0,"Oui","Non")) -> Non | M12: =IFERROR(LARGE(Journal!$P:$P,A12),"") -> 52.000005
A13: 9 | B13: =IF(M13="","",INDEX(Journal!$C:$C,MATCH(M13,Journal!$P:$P,0))) -> NEP_CT01_L | C13: =IF(M13="","",INDEX(Journal!$D:$D,MATCH(M13,Journal!$P:$P,0))) -> NEP - conductivité soude basse | D13: =IF(M13="","",INDEX(Journal!$E:$E,MATCH(M13,Journal!$P:$P,0))) -> Moyenne | E13: =IF(M13="","",INDEX(Journal!$F:$F,MATCH(M13,Journal!$P:$P,0))) -> NEP | F13: =IF(M13="","",INT(M13)) -> 39 | G13: =IF(F13="","",F13/Indicateurs!$B$5) -> 0.029191617 | H13: =IF(F13="","",SUM($F$5:F13)/Indicateurs!$B$5) -> 0.8502994 | I13: =IF(B13="","",IF(COUNTIFS(Journal!$C:$C,B13,Journal!$K:$K,1)>0,"Oui","Non")) -> Non | J13: =IF(B13="","",IF(COUNTIFS(Journal!$C:$C,B13,Journal!$L:$L,1)>0,"Oui","Non")) -> Non | K13: =IF(B13="","",IF(COUNTIFS(Journal!$C:$C,B13,Journal!$M:$M,1)>0,"Oui","Non")) -> Non | M13: =IFERROR(LARGE(Journal!$P:$P,A13),"") -> 39.000004
A14: 10 | B14: =IF(M14="","",INDEX(Journal!$C:$C,MATCH(M14,Journal!$P:$P,0))) -> CND_ST04_DEF | C14: =IF(M14="","",INDEX(Journal!$D:$D,MATCH(M14,Journal!$P:$P,0))) -> Conditionneuse 4 - défaut film | D14: =IF(M14="","",INDEX(Journal!$E:$E,MATCH(M14,Journal!$P:$P,0))) -> Moyenne | E14: =IF(M14="","",INDEX(Journal!$F:$F,MATCH(M14,Journal!$P:$P,0))) -> Conditionnement | F14: =IF(M14="","",INT(M14)) -> 27 | G14: =IF(F14="","",F14/Indicateurs!$B$5) -> 0.020209581 | H14: =IF(F14="","",SUM($F$5:F14)/Indicateurs!$B$5) -> 0.87050898 | I14: =IF(B14="","",IF(COUNTIFS(Journal!$C:$C,B14,Journal!$K:$K,1)>0,"Oui","Non")) -> Non | J14: =IF(B14="","",IF(COUNTIFS(Journal!$C:$C,B14,Journal!$L:$L,1)>0,"Oui","Non")) -> Non | K14: =IF(B14="","",IF(COUNTIFS(Journal!$C:$C,B14,Journal!$M:$M,1)>0,"Oui","Non")) -> Non | M14: =IFERROR(LARGE(Journal!$P:$P,A14),"") -> 27.000007
A16: Total top 10 | F16: =SUM(F5:F14) -> 1163 | G16: =IF(Indicateurs!$B$5=0,"",F16/Indicateurs!$B$5) -> 0.87050898
A18: Lecture : « Oui » en Intermittente ou Fugitive pointe d'abord vers un réglage (bande morte, temporisation). « Oui » en Figée pointe vers un capteur défaillant ou une alarme qui n'en est pas une. Une alarme sans action opérateur possible n'est pas une alarme : c'est un événement.

Sheet Pires périodes
A1: Les 15 fenêtres de 10 minutes les plus chargées
A2: Une avalanche se lit à partir de sa première alarme : c'est souvent l'événement déclencheur (perte d'utilité, arrêt, coupure). Journal trié par date requis pour cette colonne.
A4: Rang | B4: Début de fenêtre | C4: Fin de fenêtre | D4: Alarmes | E4: Avalanche | F4: Première alarme de la fenêtre | G4: Description | H4: clé
A5: 1 | B5: =IF(H5="","",Debut+INDEX(Journal!$H:$H,MATCH(H5,Journal!$T:$T,0))/144) -> 46085.451 | C5: =IF(B5="","",B5+1/144) -> 46085.458 | D5: =IF(H5="","",INT(H5)) -> 44 | E5: =IF(D5="","",IF(D5>SeuilAvalanche,"Oui","Non")) -> Oui | F5: =IF(H5="","",INDEX(Journal!$C:$C,MATCH(H5,Journal!$T:$T,0))) -> PAS_TT05_TRANS | G5: =IF(H5="","",INDEX(Journal!$D:$D,MATCH(H5,Journal!$T:$T,0))) -> Pasteurisateur - défaut transmetteur TT05 | H5: =IFERROR(LARGE(Journal!$T:$T,A5),"") -> 44.000051
A6: 2 | B6: =IF(H6="","",Debut+INDEX(Journal!$H:$H,MATCH(H6,Journal!$T:$T,0))/144) -> 46088.25 | C6: =IF(B6="","",B6+1/144) -> 46088.257 | D6: =IF(H6="","",INT(H6)) -> 35 | E6: =IF(D6="","",IF(D6>SeuilAvalanche,"Oui","Non")) -> Oui | F6: =IF(H6="","",INDEX(Journal!$C:$C,MATCH(H6,Journal!$T:$T,0))) -> ELEC_RES_DEF | G6: =IF(H6="","",INDEX(Journal!$D:$D,MATCH(H6,Journal!$T:$T,0))) -> Alimentation réseau - défaut phase | H6: =IFERROR(LARGE(Journal!$T:$T,A6),"") -> 35.000105
A7: 3 | B7: =IF(H7="","",Debut+INDEX(Journal!$H:$H,MATCH(H7,Journal!$T:$T,0))/144) -> 46085.444 | C7: =IF(B7="","",B7+1/144) -> 46085.451 | D7: =IF(H7="","",INT(H7)) -> 16 | E7: =IF(D7="","",IF(D7>SeuilAvalanche,"Oui","Non")) -> Oui | F7: =IF(H7="","",INDEX(Journal!$C:$C,MATCH(H7,Journal!$T:$T,0))) -> AIR_DP01_H | G7: =IF(H7="","",INDEX(Journal!$D:$D,MATCH(H7,Journal!$T:$T,0))) -> Air comprimé - filtre colmaté | H7: =IFERROR(LARGE(Journal!$T:$T,A7),"") -> 16.000049
A8: 4 | B8: =IF(H8="","",Debut+INDEX(Journal!$H:$H,MATCH(H8,Journal!$T:$T,0))/144) -> 46084.583 | C8: =IF(B8="","",B8+1/144) -> 46084.59 | D8: =IF(H8="","",INT(H8)) -> 13 | E8: =IF(D8="","",IF(D8>SeuilAvalanche,"Oui","Non")) -> Oui | F8: =IF(H8="","",INDEX(Journal!$C:$C,MATCH(H8,Journal!$T:$T,0))) -> FR02_TT01_H | G8: =IF(H8="","",INDEX(Journal!$D:$D,MATCH(H8,Journal!$T:$T,0))) -> Chambre froide 2 - température haute | H8: =IFERROR(LARGE(Journal!$T:$T,A8),"") -> 13.000034
A9: 5 | B9: =IF(H9="","",Debut+INDEX(Journal!$H:$H,MATCH(H9,Journal!$T:$T,0))/144) -> 46083.132 | C9: =IF(B9="","",B9+1/144) -> 46083.139 | D9: =IF(H9="","",INT(H9)) -> 13 | E9: =IF(D9="","",IF(D9>SeuilAvalanche,"Oui","Non")) -> Oui | F9: =IF(H9="","",INDEX(Journal!$C:$C,MATCH(H9,Journal!$T:$T,0))) -> FR02_TT01_H | G9: =IF(H9="","",INDEX(Journal!$D:$D,MATCH(H9,Journal!$T:$T,0))) -> Chambre froide 2 - température haute | H9: =IFERROR(LARGE(Journal!$T:$T,A9),"") -> 13.000001
A10: 6 | B10: =IF(H10="","",Debut+INDEX(Journal!$H:$H,MATCH(H10,Journal!$T:$T,0))/144) -> 46088.819 | C10: =IF(B10="","",B10+1/144) -> 46088.826 | D10: =IF(H10="","",INT(H10)) -> 12 | E10: =IF(D10="","",IF(D10>SeuilAvalanche,"Oui","Non")) -> Oui | F10: =IF(H10="","",INDEX(Journal!$C:$C,MATCH(H10,Journal!$T:$T,0))) -> CND_ST01_ARR | G10: =IF(H10="","",INDEX(Journal!$D:$D,MATCH(H10,Journal!$T:$T,0))) -> Conditionneuse 1 - machine à l'arrêt | H10: =IFERROR(LARGE(Journal!$T:$T,A10),"") -> 12.000124
A11: 7 | B11: =IF(H11="","",Debut+INDEX(Journal!$H:$H,MATCH(H11,Journal!$T:$T,0))/144) -> 46087.569 | C11: =IF(B11="","",B11+1/144) -> 46087.576 | D11: =IF(H11="","",INT(H11)) -> 12 | E11: =IF(D11="","",IF(D11>SeuilAvalanche,"Oui","Non")) -> Oui | F11: =IF(H11="","",INDEX(Journal!$C:$C,MATCH(H11,Journal!$T:$T,0))) -> FR02_TT01_H | G11: =IF(H11="","",INDEX(Journal!$D:$D,MATCH(H11,Journal!$T:$T,0))) -> Chambre froide 2 - température haute | H11: =IFERROR(LARGE(Journal!$T:$T,A11),"") -> 12.000093
A12: 8 | B12: =IF(H12="","",Debut+INDEX(Journal!$H:$H,MATCH(H12,Journal!$T:$T,0))/144) -> 46085.479 | C12: =IF(B12="","",B12+1/144) -> 46085.486 | D12: =IF(H12="","",INT(H12)) -> 12 | E12: =IF(D12="","",IF(D12>SeuilAvalanche,"Oui","Non")) -> Oui | F12: =IF(H12="","",INDEX(Journal!$C:$C,MATCH(H12,Journal!$T:$T,0))) -> AIR_PT01_L | G12: =IF(H12="","",INDEX(Journal!$D:$D,MATCH(H12,Journal!$T:$T,0))) -> Air comprimé - pression réseau basse | H12: =IFERROR(LARGE(Journal!$T:$T,A12),"") -> 12.000056
A13: 9 | B13: =IF(H13="","",Debut+INDEX(Journal!$H:$H,MATCH(H13,Journal!$T:$T,0))/144) -> 46088.361 | C13: =IF(B13="","",B13+1/144) -> 46088.368 | D13: =IF(H13="","",INT(H13)) -> 11 | E13: =IF(D13="","",IF(D13>SeuilAvalanche,"Oui","Non")) -> Oui | F13: =IF(H13="","",INDEX(Journal!$C:$C,MATCH(H13,Journal!$T:$T,0))) -> REC_FT01_DEV | G13: =IF(H13="","",INDEX(Journal!$D:$D,MATCH(H13,Journal!$T:$T,0))) -> Réception - écart débitmètre / bon de livraison | H13: =IFERROR(LARGE(Journal!$T:$T,A13),"") -> 11.000111
A14: 10 | B14: =IF(H14="","",Debut+INDEX(Journal!$H:$H,MATCH(H14,Journal!$T:$T,0))/144) -> 46084.535 | C14: =IF(B14="","",B14+1/144) -> 46084.542 | D14: =IF(H14="","",INT(H14)) -> 11 | E14: =IF(D14="","",IF(D14>SeuilAvalanche,"Oui","Non")) -> Oui | F14: =IF(H14="","",INDEX(Journal!$C:$C,MATCH(H14,Journal!$T:$T,0))) -> CND_ST01_ARR | G14: =IF(H14="","",INDEX(Journal!$D:$D,MATCH(H14,Journal!$T:$T,0))) -> Conditionneuse 1 - machine à l'arrêt | H14: =IFERROR(LARGE(Journal!$T:$T,A14),"") -> 11.000032
A15: 11 | B15: =IF(H15="","",Debut+INDEX(Journal!$H:$H,MATCH(H15,Journal!$T:$T,0))/144) -> 46084.458 | C15: =IF(B15="","",B15+1/144) -> 46084.465 | D15: =IF(H15="","",INT(H15)) -> 11 | E15: =IF(D15="","",IF(D15>SeuilAvalanche,"Oui","Non")) -> Oui | F15: =IF(H15="","",INDEX(Journal!$C:$C,MATCH(H15,Journal!$T:$T,0))) -> FR01_PORTE | G15: =IF(H15="","",INDEX(Journal!$D:$D,MATCH(H15,Journal!$T:$T,0))) -> Chambre froide 1 - porte ouverte > 5 min | H15: =IFERROR(LARGE(Journal!$T:$T,A15),"") -> 11.00003
A16: 12 | B16: =IF(H16="","",Debut+INDEX(Journal!$H:$H,MATCH(H16,Journal!$T:$T,0))/144) -> 46084.389 | C16: =IF(B16="","",B16+1/144) -> 46084.396 | D16: =IF(H16="","",INT(H16)) -> 11 | E16: =IF(D16="","",IF(D16>SeuilAvalanche,"Oui","Non")) -> Oui | F16: =IF(H16="","",INDEX(Journal!$C:$C,MATCH(H16,Journal!$T:$T,0))) -> FR01_PORTE | G16: =IF(H16="","",INDEX(Journal!$D:$D,MATCH(H16,Journal!$T:$T,0))) -> Chambre froide 1 - porte ouverte > 5 min | H16: =IFERROR(LARGE(Journal!$T:$T,A16),"") -> 11.000026
... A19: 15 | B19: =IF(H19="","",Debut+INDEX(Journal!$H:$H,MATCH(H19,Journal!$T:$T,0))/144) -> 46087.653 | C19: =IF(B19="","",B19+1/144) -> 46087.66 | D19: =IF(H19="","",INT(H19)) -> 10 | E19: =IF(D19="","",IF(D19>SeuilAvalanche,"Oui","Non")) -> Non | F19: =IF(H19="","",INDEX(Journal!$C:$C,MATCH(H19,Journal!$T:$T,0))) -> FR02_TT01_H | G19: =IF(H19="","",INDEX(Journal!$D:$D,MATCH(H19,Journal!$T:$T,0))) -> Chambre froide 2 - température haute | H19: =IFERROR(LARGE(Journal!$T:$T,A19),"") -> 10.000096

Sheet Journal
A1: horodatage_activation | B1: horodatage_retour | C1: tag | D1: description | E1: priorite | F1: zone | G1: dans_periode | H1: fenetre_10min | I1: fenetre_heure | J1: duree_s | K1: intermittente | L1: fugitive | M1: figee | N1: nb_dans_fenetre_10min | O1: nb_dans_heure | P1: cle_occurrences_tag | Q1: tag_intermittent | R1: tag_fige | S1: tag_fugitif | T1: cle_fenetre | U1: active_fin_periode
A2: 46083.081 | B2: 46083.081 | C2: FR02_TT01_H | D2: Chambre froide 2 - température haute | E2: Haute | F2: Froid | G2: =IF(A2="","",IF(AND(A2>=Debut,A2<Fin),1,0)) -> 1 | H2: =IF(G2=1,INT(ROUND((A2-Debut)*86400,0)/600),"") -> 11 | I2: =IF(G2=1,INT(ROUND((A2-Debut)*86400,0)/3600),"") -> 1 | J2: =IF(OR(A2="",B2=""),"",ROUND((B2-A2)*86400,0)) -> 14 | K2: =IF(G2=1,IF(COUNTIFS($C:$C,C2,$G:$G,1,$A:$A,">="&(A2-FenetreInterm/86400),$A:$A,"<="&A2)>=NbInterm,1,0),"") -> 0 | L2: =IF(G2=1,IF(B2="",0,IF(J2<SeuilFugitive,1,0)),"") -> 0 | M2: =IF(G2=1,IF(B2="",IF((Fin-A2)*24>SeuilFigee,1,0),IF(J2>SeuilFigee*3600,1,0)),"") -> 0 | N2: =IF(G2=1,IF(COUNTIF(H$2:H2,H2)=1,COUNTIF($H:$H,H2),""),"") -> 4 | O2: =IF(G2=1,IF(COUNTIF(I$2:I2,I2)=1,COUNTIF($I:$I,I2),""),"") -> 4 | P2: =IF(G2=1,IF(COUNTIFS(C$2:C2,C2,G$2:G2,1)=1,COUNTIFS($C:$C,C2,$G:$G,1)+ROW()/10000000,""),"") -> 431 | Q2: =IF(K2=1,IF(COUNTIFS(C$2:C2,C2,K$2:K2,1)=1,1,0),"") | R2: =IF(M2=1,IF(COUNTIFS(C$2:C2,C2,M$2:M2,1)=1,1,0),"") | S2: =IF(L2=1,IF(COUNTIFS(C$2:C2,C2,L$2:L2,1)=1,1,0),"") | T2: =IF(N2="","",N2+ROW()/10000000) -> 4.0000002 | U2: =IF(G2=1,IF(B2="",1,0),"") -> 0
A3: 46083.081 | B3: 46083.081 | C3: FR02_TT01_H | D3: Chambre froide 2 - température haute | E3: Haute | F3: Froid | G3: =IF(A3="","",IF(AND(A3>=Debut,A3<Fin),1,0)) -> 1 | H3: =IF(G3=1,INT(ROUND((A3-Debut)*86400,0)/600),"") -> 11 | I3: =IF(G3=1,INT(ROUND((A3-Debut)*86400,0)/3600),"") -> 1 | J3: =IF(OR(A3="",B3=""),"",ROUND((B3-A3)*86400,0)) -> 18 | K3: =IF(G3=1,IF(COUNTIFS($C:$C,C3,$G:$G,1,$A:$A,">="&(A3-FenetreInterm/86400),$A:$A,"<="&A3)>=NbInterm,1,0),"") -> 0 | L3: =IF(G3=1,IF(B3="",0,IF(J3<SeuilFugitive,1,0)),"") -> 0 | M3: =IF(G3=1,IF(B3="",IF((Fin-A3)*24>SeuilFigee,1,0),IF(J3>SeuilFigee*3600,1,0)),"") -> 0 | N3: =IF(G3=1,IF(COUNTIF(H$2:H3,H3)=1,COUNTIF($H:$H,H3),""),"") | O3: =IF(G3=1,IF(COUNTIF(I$2:I3,I3)=1,COUNTIF($I:$I,I3),""),"") | P3: =IF(G3=1,IF(COUNTIFS(C$2:C3,C3,G$2:G3,1)=1,COUNTIFS($C:$C,C3,$G:$G,1)+ROW()/10000000,""),"") | Q3: =IF(K3=1,IF(COUNTIFS(C$2:C3,C3,K$2:K3,1)=1,1,0),"") | R3: =IF(M3=1,IF(COUNTIFS(C$2:C3,C3,M$2:M3,1)=1,1,0),"") | S3: =IF(L3=1,IF(COUNTIFS(C$2:C3,C3,L$2:L3,1)=1,1,0),"") | T3: =IF(N3="","",N3+ROW()/10000000) | U3: =IF(G3=1,IF(B3="",1,0),"") -> 0
A4: 46083.081 | B4: 46083.081 | C4: FR02_TT01_H | D4: Chambre froide 2 - température haute | E4: Haute | F4: Froid | G4: =IF(A4="","",IF(AND(A4>=Debut,A4<Fin),1,0)) -> 1 | H4: =IF(G4=1,INT(ROUND((A4-Debut)*86400,0)/600),"") -> 11 | I4: =IF(G4=1,INT(ROUND((A4-Debut)*86400,0)/3600),"") -> 1 | J4: =IF(OR(A4="",B4=""),"",ROUND((B4-A4)*86400,0)) -> 10 | K4: =IF(G4=1,IF(COUNTIFS($C:$C,C4,$G:$G,1,$A:$A,">="&(A4-FenetreInterm/86400),$A:$A,"<="&A4)>=NbInterm,1,0),"") -> 1 | L4: =IF(G4=1,IF(B4="",0,IF(J4<SeuilFugitive,1,0)),"") -> 0 | M4: =IF(G4=1,IF(B4="",IF((Fin-A4)*24>SeuilFigee,1,0),IF(J4>SeuilFigee*3600,1,0)),"") -> 0 | N4: =IF(G4=1,IF(COUNTIF(H$2:H4,H4)=1,COUNTIF($H:$H,H4),""),"") | O4: =IF(G4=1,IF(COUNTIF(I$2:I4,I4)=1,COUNTIF($I:$I,I4),""),"") | P4: =IF(G4=1,IF(COUNTIFS(C$2:C4,C4,G$2:G4,1)=1,COUNTIFS($C:$C,C4,$G:$G,1)+ROW()/10000000,""),"") | Q4: =IF(K4=1,IF(COUNTIFS(C$2:C4,C4,K$2:K4,1)=1,1,0),"") -> 1 | R4: =IF(M4=1,IF(COUNTIFS(C$2:C4,C4,M$2:M4,1)=1,1,0),"") | S4: =IF(L4=1,IF(COUNTIFS(C$2:C4,C4,L$2:L4,1)=1,1,0),"") | T4: =IF(N4="","",N4+ROW()/10000000) | U4: =IF(G4=1,IF(B4="",1,0),"") -> 0
A5: 46083.081 | B5: 46083.082 | C5: FR02_TT01_H | D5: Chambre froide 2 - température haute | E5: Haute | F5: Froid | G5: =IF(A5="","",IF(AND(A5>=Debut,A5<Fin),1,0)) -> 1 | H5: =IF(G5=1,INT(ROUND((A5-Debut)*86400,0)/600),"") -> 11 | I5: =IF(G5=1,INT(ROUND((A5-Debut)*86400,0)/3600),"") -> 1 | J5: =IF(OR(A5="",B5=""),"",ROUND((B5-A5)*86400,0)) -> 12 | K5: =IF(G5=1,IF(COUNTIFS($C:$C,C5,$G:$G,1,$A:$A,">="&(A5-FenetreInterm/86400),$A:$A,"<="&A5)>=NbInterm,1,0),"") -> 1 | L5: =IF(G5=1,IF(B5="",0,IF(J5<SeuilFugitive,1,0)),"") -> 0 | M5: =IF(G5=1,IF(B5="",IF((Fin-A5)*24>SeuilFigee,1,0),IF(J5>SeuilFigee*3600,1,0)),"") -> 0 | N5: =IF(G5=1,IF(COUNTIF(H$2:H5,H5)=1,COUNTIF($H:$H,H5),""),"") | O5: =IF(G5=1,IF(COUNTIF(I$2:I5,I5)=1,COUNTIF($I:$I,I5),""),"") | P5: =IF(G5=1,IF(COUNTIFS(C$2:C5,C5,G$2:G5,1)=1,COUNTIFS($C:$C,C5,$G:$G,1)+ROW()/10000000,""),"") | Q5: =IF(K5=1,IF(COUNTIFS(C$2:C5,C5,K$2:K5,1)=1,1,0),"") -> 0 | R5: =IF(M5=1,IF(COUNTIFS(C$2:C5,C5,M$2:M5,1)=1,1,0),"") | S5: =IF(L5=1,IF(COUNTIFS(C$2:C5,C5,L$2:L5,1)=1,1,0),"") | T5: =IF(N5="","",N5+ROW()/10000000) | U5: =IF(G5=1,IF(B5="",1,0),"") -> 0
A6: 46083.088 | B6: 46083.089 | C6: FR02_TT01_H | D6: Chambre froide 2 - température haute | E6: Haute | F6: Froid | G6: =IF(A6="","",IF(AND(A6>=Debut,A6<Fin),1,0)) -> 1 | H6: =IF(G6=1,INT(ROUND((A6-Debut)*86400,0)/600),"") -> 12 | I6: =IF(G6=1,INT(ROUND((A6-Debut)*86400,0)/3600),"") -> 2 | J6: =IF(OR(A6="",B6=""),"",ROUND((B6-A6)*86400,0)) -> 21 | K6: =IF(G6=1,IF(COUNTIFS($C:$C,C6,$G:$G,1,$A:$A,">="&(A6-FenetreInterm/86400),$A:$A,"<="&A6)>=NbInterm,1,0),"") -> 0 | L6: =IF(G6=1,IF(B6="",0,IF(J6<SeuilFugitive,1,0)),"") -> 0 | M6: =IF(G6=1,IF(B6="",IF((Fin-A6)*24>SeuilFigee,1,0),IF(J6>SeuilFigee*3600,1,0)),"") -> 0 | N6: =IF(G6=1,IF(COUNTIF(H$2:H6,H6)=1,COUNTIF($H:$H,H6),""),"") -> 4 | O6: =IF(G6=1,IF(COUNTIF(I$2:I6,I6)=1,COUNTIF($I:$I,I6),""),"") -> 8 | P6: =IF(G6=1,IF(COUNTIFS(C$2:C6,C6,G$2:G6,1)=1,COUNTIFS($C:$C,C6,$G:$G,1)+ROW()/10000000,""),"") | Q6: =IF(K6=1,IF(COUNTIFS(C$2:C6,C6,K$2:K6,1)=1,1,0),"") | R6: =IF(M6=1,IF(COUNTIFS(C$2:C6,C6,M$2:M6,1)=1,1,0),"") | S6: =IF(L6=1,IF(COUNTIFS(C$2:C6,C6,L$2:L6,1)=1,1,0),"") | T6: =IF(N6="","",N6+ROW()/10000000) -> 4.0000006 | U6: =IF(G6=1,IF(B6="",1,0),"") -> 0
A7: 46083.088 | B7: 46083.089 | C7: FR02_TT01_H | D7: Chambre froide 2 - température haute | E7: Haute | F7: Froid | G7: =IF(A7="","",IF(AND(A7>=Debut,A7<Fin),1,0)) -> 1 | H7: =IF(G7=1,INT(ROUND((A7-Debut)*86400,0)/600),"") -> 12 | I7: =IF(G7=1,INT(ROUND((A7-Debut)*86400,0)/3600),"") -> 2 | J7: =IF(OR(A7="",B7=""),"",ROUND((B7-A7)*86400,0)) -> 22 | K7: =IF(G7=1,IF(COUNTIFS($C:$C,C7,$G:$G,1,$A:$A,">="&(A7-FenetreInterm/86400),$A:$A,"<="&A7)>=NbInterm,1,0),"") -> 0 | L7: =IF(G7=1,IF(B7="",0,IF(J7<SeuilFugitive,1,0)),"") -> 0 | M7: =IF(G7=1,IF(B7="",IF((Fin-A7)*24>SeuilFigee,1,0),IF(J7>SeuilFigee*3600,1,0)),"") -> 0 | N7: =IF(G7=1,IF(COUNTIF(H$2:H7,H7)=1,COUNTIF($H:$H,H7),""),"") | O7: =IF(G7=1,IF(COUNTIF(I$2:I7,I7)=1,COUNTIF($I:$I,I7),""),"") | P7: =IF(G7=1,IF(COUNTIFS(C$2:C7,C7,G$2:G7,1)=1,COUNTIFS($C:$C,C7,$G:$G,1)+ROW()/10000000,""),"") | Q7: =IF(K7=1,IF(COUNTIFS(C$2:C7,C7,K$2:K7,1)=1,1,0),"") | R7: =IF(M7=1,IF(COUNTIFS(C$2:C7,C7,M$2:M7,1)=1,1,0),"") | S7: =IF(L7=1,IF(COUNTIFS(C$2:C7,C7,L$2:L7,1)=1,1,0),"") | T7: =IF(N7="","",N7+ROW()/10000000) | U7: =IF(G7=1,IF(B7="",1,0),"") -> 0
A8: 46083.089 | B8: 46083.089 | C8: FR02_TT01_H | D8: Chambre froide 2 - température haute | E8: Haute | F8: Froid | G8: =IF(A8="","",IF(AND(A8>=Debut,A8<Fin),1,0)) -> 1 | H8: =IF(G8=1,INT(ROUND((A8-Debut)*86400,0)/600),"") -> 12 | I8: =IF(G8=1,INT(ROUND((A8-Debut)*86400,0)/3600),"") -> 2 | J8: =IF(OR(A8="",B8=""),"",ROUND((B8-A8)*86400,0)) -> 20 | K8: =IF(G8=1,IF(COUNTIFS($C:$C,C8,$G:$G,1,$A:$A,">="&(A8-FenetreInterm/86400),$A:$A,"<="&A8)>=NbInterm,1,0),"") -> 1 | L8: =IF(G8=1,IF(B8="",0,IF(J8<SeuilFugitive,1,0)),"") -> 0 | M8: =IF(G8=1,IF(B8="",IF((Fin-A8)*24>SeuilFigee,1,0),IF(J8>SeuilFigee*3600,1,0)),"") -> 0 | N8: =IF(G8=1,IF(COUNTIF(H$2:H8,H8)=1,COUNTIF($H:$H,H8),""),"") | O8: =IF(G8=1,IF(COUNTIF(I$2:I8,I8)=1,COUNTIF($I:$I,I8),""),"") | P8: =IF(G8=1,IF(COUNTIFS(C$2:C8,C8,G$2:G8,1)=1,COUNTIFS($C:$C,C8,$G:$G,1)+ROW()/10000000,""),"") | Q8: =IF(K8=1,IF(COUNTIFS(C$2:C8,C8,K$2:K8,1)=1,1,0),"") -> 0 | R8: =IF(M8=1,IF(COUNTIFS(C$2:C8,C8,M$2:M8,1)=1,1,0),"") | S8: =IF(L8=1,IF(COUNTIFS(C$2:C8,C8,L$2:L8,1)=1,1,0),"") | T8: =IF(N8="","",N8+ROW()/10000000) | U8: =IF(G8=1,IF(B8="",1,0),"") -> 0
A9: 46083.089 | B9: 46083.089 | C9: FR02_TT01_H | D9: Chambre froide 2 - température haute | E9: Haute | F9: Froid | G9: =IF(A9="","",IF(AND(A9>=Debut,A9<Fin),1,0)) -> 1 | H9: =IF(G9=1,INT(ROUND((A9-Debut)*86400,0)/600),"") -> 12 | I9: =IF(G9=1,INT(ROUND((A9-Debut)*86400,0)/3600),"") -> 2 | J9: =IF(OR(A9="",B9=""),"",ROUND((B9-A9)*86400,0)) -> 12 | K9: =IF(G9=1,IF(COUNTIFS($C:$C,C9,$G:$G,1,$A:$A,">="&(A9-FenetreInterm/86400),$A:$A,"<="&A9)>=NbInterm,1,0),"") -> 1 | L9: =IF(G9=1,IF(B9="",0,IF(J9<SeuilFugitive,1,0)),"") -> 0 | M9: =IF(G9=1,IF(B9="",IF((Fin-A9)*24>SeuilFigee,1,0),IF(J9>SeuilFigee*3600,1,0)),"") -> 0 | N9: =IF(G9=1,IF(COUNTIF(H$2:H9,H9)=1,COUNTIF($H:$H,H9),""),"") | O9: =IF(G9=1,IF(COUNTIF(I$2:I9,I9)=1,COUNTIF($I:$I,I9),""),"") | P9: =IF(G9=1,IF(COUNTIFS(C$2:C9,C9,G$2:G9,1)=1,COUNTIFS($C:$C,C9,$G:$G,1)+ROW()/10000000,""),"") | Q9: =IF(K9=1,IF(COUNTIFS(C$2:C9,C9,K$2:K9,1)=1,1,0),"") -> 0 | R9: =IF(M9=1,IF(COUNTIFS(C$2:C9,C9,M$2:M9,1)=1,1,0),"") | S9: =IF(L9=1,IF(COUNTIFS(C$2:C9,C9,L$2:L9,1)=1,1,0),"") | T9: =IF(N9="","",N9+ROW()/10000000) | U9: =IF(G9=1,IF(B9="",1,0),"") -> 0
A10: 46083.105 | B10: 46083.105 | C10: FR02_TT01_H | D10: Chambre froide 2 - température haute | E10: Haute | F10: Froid | G10: =IF(A10="","",IF(AND(A10>=Debut,A10<Fin),1,0)) -> 1 | H10: =IF(G10=1,INT(ROUND((A10-Debut)*86400,0)/600),"") -> 15 | I10: =IF(G10=1,INT(ROUND((A10-Debut)*86400,0)/3600),"") -> 2 | J10: =IF(OR(A10="",B10=""),"",ROUND((B10-A10)*86400,0)) -> 16 | K10: =IF(G10=1,IF(COUNTIFS($C:$C,C10,$G:$G,1,$A:$A,">="&(A10-FenetreInterm/86400),$A:$A,"<="&A10)>=NbInterm,1,0),"") -> 0 | L10: =IF(G10=1,IF(B10="",0,IF(J10<SeuilFugitive,1,0)),"") -> 0 | M10: =IF(G10=1,IF(B10="",IF((Fin-A10)*24>SeuilFigee,1,0),IF(J10>SeuilFigee*3600,1,0)),"") -> 0 | N10: =IF(G10=1,IF(COUNTIF(H$2:H10,H10)=1,COUNTIF($H:$H,H10),""),"") -> 3 | O10: =IF(G10=1,IF(COUNTIF(I$2:I10,I10)=1,COUNTIF($I:$I,I10),""),"") | P10: =IF(G10=1,IF(COUNTIFS(C$2:C10,C10,G$2:G10,1)=1,COUNTIFS($C:$C,C10,$G:$G,1)+ROW()/10000000,""),"") | Q10: =IF(K10=1,IF(COUNTIFS(C$2:C10,C10,K$2:K10,1)=1,1,0),"") | R10: =IF(M10=1,IF(COUNTIFS(C$2:C10,C10,M$2:M10,1)=1,1,0),"") | S10: =IF(L10=1,IF(COUNTIFS(C$2:C10,C10,L$2:L10,1)=1,1,0),"") | T10: =IF(N10="","",N10+ROW()/10000000) -> 3.000001 | U10: =IF(G10=1,IF(B10="",1,0),"") -> 0
A11: 46083.105 | B11: 46083.105 | C11: FR02_TT01_H | D11: Chambre froide 2 - température haute | E11: Haute | F11: Froid | G11: =IF(A11="","",IF(AND(A11>=Debut,A11<Fin),1,0)) -> 1 | H11: =IF(G11=1,INT(ROUND((A11-Debut)*86400,0)/600),"") -> 15 | I11: =IF(G11=1,INT(ROUND((A11-Debut)*86400,0)/3600),"") -> 2 | J11: =IF(OR(A11="",B11=""),"",ROUND((B11-A11)*86400,0)) -> 14 | K11: =IF(G11=1,IF(COUNTIFS($C:$C,C11,$G:$G,1,$A:$A,">="&(A11-FenetreInterm/86400),$A:$A,"<="&A11)>=NbInterm,1,0),"") -> 0 | L11: =IF(G11=1,IF(B11="",0,IF(J11<SeuilFugitive,1,0)),"") -> 0 | M11: =IF(G11=1,IF(B11="",IF((Fin-A11)*24>SeuilFigee,1,0),IF(J11>SeuilFigee*3600,1,0)),"") -> 0 | N11: =IF(G11=1,IF(COUNTIF(H$2:H11,H11)=1,COUNTIF($H:$H,H11),""),"") | O11: =IF(G11=1,IF(COUNTIF(I$2:I11,I11)=1,COUNTIF($I:$I,I11),""),"") | P11: =IF(G11=1,IF(COUNTIFS(C$2:C11,C11,G$2:G11,1)=1,COUNTIFS($C:$C,C11,$G:$G,1)+ROW()/10000000,""),"") | Q11: =IF(K11=1,IF(COUNTIFS(C$2:C11,C11,K$2:K11,1)=1,1,0),"") | R11: =IF(M11=1,IF(COUNTIFS(C$2:C11,C11,M$2:M11,1)=1,1,0),"") | S11: =IF(L11=1,IF(COUNTIFS(C$2:C11,C11,L$2:L11,1)=1,1,0),"") | T11: =IF(N11="","",N11+ROW()/10000000) | U11: =IF(G11=1,IF(B11="",1,0),"") -> 0
A12: 46083.105 | B12: 46083.105 | C12: FR02_TT01_H | D12: Chambre froide 2 - température haute | E12: Haute | F12: Froid | G12: =IF(A12="","",IF(AND(A12>=Debut,A12<Fin),1,0)) -> 1 | H12: =IF(G12=1,INT(ROUND((A12-Debut)*86400,0)/600),"") -> 15 | I12: =IF(G12=1,INT(ROUND((A12-Debut)*86400,0)/3600),"") -> 2 | J12: =IF(OR(A12="",B12=""),"",ROUND((B12-A12)*86400,0)) -> 9 | K12: =IF(G12=1,IF(COUNTIFS($C:$C,C12,$G:$G,1,$A:$A,">="&(A12-FenetreInterm/86400),$A:$A,"<="&A12)>=NbInterm,1,0),"") -> 1 | L12: =IF(G12=1,IF(B12="",0,IF(J12<SeuilFugitive,1,0)),"") -> 0 | M12: =IF(G12=1,IF(B12="",IF((Fin-A12)*24>SeuilFigee,1,0),IF(J12>SeuilFigee*3600,1,0)),"") -> 0 | N12: =IF(G12=1,IF(COUNTIF(H$2:H12,H12)=1,COUNTIF($H:$H,H12),""),"") | O12: =IF(G12=1,IF(COUNTIF(I$2:I12,I12)=1,COUNTIF($I:$I,I12),""),"") | P12: =IF(G12=1,IF(COUNTIFS(C$2:C12,C12,G$2:G12,1)=1,COUNTIFS($C:$C,C12,$G:$G,1)+ROW()/10000000,""),"") | Q12: =IF(K12=1,IF(COUNTIFS(C$2:C12,C12,K$2:K12,1)=1,1,0),"") -> 0 | R12: =IF(M12=1,IF(COUNTIFS(C$2:C12,C12,M$2:M12,1)=1,1,0),"") | S12: =IF(L12=1,IF(COUNTIFS(C$2:C12,C12,L$2:L12,1)=1,1,0),"") | T12: =IF(N12="","",N12+ROW()/10000000) | U12: =IF(G12=1,IF(B12="",1,0),"") -> 0
A13: 46083.112 | B13: 46083.162 | C13: AIR_DP01_H | D13: Air comprimé - filtre colmaté | E13: Basse | F13: Utilités | G13: =IF(A13="","",IF(AND(A13>=Debut,A13<Fin),1,0)) -> 1 | H13: =IF(G13=1,INT(ROUND((A13-Debut)*86400,0)/600),"") -> 16 | I13: =IF(G13=1,INT(ROUND((A13-Debut)*86400,0)/3600),"") -> 2 | J13: =IF(OR(A13="",B13=""),"",ROUND((B13-A13)*86400,0)) -> 4268 | K13: =IF(G13=1,IF(COUNTIFS($C:$C,C13,$G:$G,1,$A:$A,">="&(A13-FenetreInterm/86400),$A:$A,"<="&A13)>=NbInterm,1,0),"") -> 0 | L13: =IF(G13=1,IF(B13="",0,IF(J13<SeuilFugitive,1,0)),"") -> 0 | M13: =IF(G13=1,IF(B13="",IF((Fin-A13)*24>SeuilFigee,1,0),IF(J13>SeuilFigee*3600,1,0)),"") -> 0 | N13: =IF(G13=1,IF(COUNTIF(H$2:H13,H13)=1,COUNTIF($H:$H,H13),""),"") -> 1 | O13: =IF(G13=1,IF(COUNTIF(I$2:I13,I13)=1,COUNTIF($I:$I,I13),""),"") | P13: =IF(G13=1,IF(COUNTIFS(C$2:C13,C13,G$2:G13,1)=1,COUNTIFS($C:$C,C13,$G:$G,1)+ROW()/10000000,""),"") -> 16.000001 | Q13: =IF(K13=1,IF(COUNTIFS(C$2:C13,C13,K$2:K13,1)=1,1,0),"") | R13: =IF(M13=1,IF(COUNTIFS(C$2:C13,C13,M$2:M13,1)=1,1,0),"") | S13: =IF(L13=1,IF(COUNTIFS(C$2:C13,C13,L$2:L13,1)=1,1,0),"") | T13: =IF(N13="","",N13+ROW()/10000000) -> 1.0000013 | U13: =IF(G13=1,IF(B13="",1,0),"") -> 0
... A17: 46083.134 | B17: 46083.134 | C17: FR02_TT01_H | D17: Chambre froide 2 - température haute | E17: Haute | F17: Froid | G17: =IF(A17="","",IF(AND(A17>=Debut,A17<Fin),1,0)) -> 1 | H17: =IF(G17=1,INT(ROUND((A17-Debut)*86400,0)/600),"") -> 19 | I17: =IF(G17=1,INT(ROUND((A17-Debut)*86400,0)/3600),"") -> 3 | J17: =IF(OR(A17="",B17=""),"",ROUND((B17-A17)*86400,0)) -> 11 | K17: =IF(G17=1,IF(COUNTIFS($C:$C,C17,$G:$G,1,$A:$A,">="&(A17-FenetreInterm/86400),$A:$A,"<="&A17)>=NbInterm,1,0),"") -> 1 | L17: =IF(G17=1,IF(B17="",0,IF(J17<SeuilFugitive,1,0)),"") -> 0 | M17: =IF(G17=1,IF(B17="",IF((Fin-A17)*24>SeuilFigee,1,0),IF(J17>SeuilFigee*3600,1,0)),"") -> 0 | N17: =IF(G17=1,IF(COUNTIF(H$2:H17,H17)=1,COUNTIF($H:$H,H17),""),"") | O17: =IF(G17=1,IF(COUNTIF(I$2:I17,I17)=1,COUNTIF($I:$I,I17),""),"") | P17: =IF(G17=1,IF(COUNTIFS(C$2:C17,C17,G$2:G17,1)=1,COUNTIFS($C:$C,C17,$G:$G,1)+ROW()/10000000,""),"") | Q17: =IF(K17=1,IF(COUNTIFS(C$2:C17,C17,K$2:K17,1)=1,1,0),"") -> 0 | R17: =IF(M17=1,IF(COUNTIFS(C$2:C17,C17,M$2:M17,1)=1,1,0),"") | S17: =IF(L17=1,IF(COUNTIFS(C$2:C17,C17,L$2:L17,1)=1,1,0),"") | T17: =IF(N17="","",N17+ROW()/10000000) | U17: =IF(G17=1,IF(B17="",1,0),"") -> 0
A18: 46083.134 | C18: TK03_LSH | D18: Tank lait cru 3 - niveau très haut | E18: Haute | F18: Réception | G18: =IF(A18="","",IF(AND(A18>=Debut,A18<Fin),1,0)) -> 1 | H18: =IF(G18=1,INT(ROUND((A18-Debut)*86400,0)/600),"") -> 19 | I18: =IF(G18=1,INT(ROUND((A18-Debut)*86400,0)/3600),"") -> 3 | J18: =IF(OR(A18="",B18=""),"",ROUND((B18-A18)*86400,0)) | K18: =IF(G18=1,IF(COUNTIFS($C:$C,C18,$G:$G,1,$A:$A,">="&(A18-FenetreInterm/86400),$A:$A,"<="&A18)>=NbInterm,1,0),"") -> 0 | L18: =IF(G18=1,IF(B18="",0,IF(J18<SeuilFugitive,1,0)),"") -> 0 | M18: =IF(G18=1,IF(B18="",IF((Fin-A18)*24>SeuilFigee,1,0),IF(J18>SeuilFigee*3600,1,0)),"") -> 1 | N18: =IF(G18=1,IF(COUNTIF(H$2:H18,H18)=1,COUNTIF($H:$H,H18),""),"") | O18: =IF(G18=1,IF(COUNTIF(I$2:I18,I18)=1,COUNTIF($I:$I,I18),""),"") | P18: =IF(G18=1,IF(COUNTIFS(C$2:C18,C18,G$2:G18,1)=1,COUNTIFS($C:$C,C18,$G:$G,1)+ROW()/10000000,""),"") -> 1.0000018 | Q18: =IF(K18=1,IF(COUNTIFS(C$2:C18,C18,K$2:K18,1)=1,1,0),"") | R18: =IF(M18=1,IF(COUNTIFS(C$2:C18,C18,M$2:M18,1)=1,1,0),"") -> 1 | S18: =IF(L18=1,IF(COUNTIFS(C$2:C18,C18,L$2:L18,1)=1,1,0),"") | T18: =IF(N18="","",N18+ROW()/10000000) | U18: =IF(G18=1,IF(B18="",1,0),"") -> 1
A19: 46083.134 | B19: 46083.134 | C19: FR02_TT01_H | D19: Chambre froide 2 - température haute | E19: Haute | F19: Froid | G19: =IF(A19="","",IF(AND(A19>=Debut,A19<Fin),1,0)) -> 1 | H19: =IF(G19=1,INT(ROUND((A19-Debut)*86400,0)/600),"") -> 19 | I19: =IF(G19=1,INT(ROUND((A19-Debut)*86400,0)/3600),"") -> 3 | J19: =IF(OR(A19="",B19=""),"",ROUND((B19-A19)*86400,0)) -> 19 | K19: =IF(G19=1,IF(COUNTIFS($C:$C,C19,$G:$G,1,$A:$A,">="&(A19-FenetreInterm/86400),$A:$A,"<="&A19)>=NbInterm,1,0),"") -> 1 | L19: =IF(G19=1,IF(B19="",0,IF(J19<SeuilFugitive,1,0)),"") -> 0 | M19: =IF(G19=1,IF(B19="",IF((Fin-A19)*24>SeuilFigee,1,0),IF(J19>SeuilFigee*3600,1,0)),"") -> 0 | N19: =IF(G19=1,IF(COUNTIF(H$2:H19,H19)=1,COUNTIF($H:$H,H19),""),"") | O19: =IF(G19=1,IF(COUNTIF(I$2:I19,I19)=1,COUNTIF($I:$I,I19),""),"") | P19: =IF(G19=1,IF(COUNTIFS(C$2:C19,C19,G$2:G19,1)=1,COUNTIFS($C:$C,C19,$G:$G,1)+ROW()/10000000,""),"") | Q19: =IF(K19=1,IF(COUNTIFS(C$2:C19,C19,K$2:K19,1)=1,1,0),"") -> 0 | R19: =IF(M19=1,IF(COUNTIFS(C$2:C19,C19,M$2:M19,1)=1,1,0),"") | S19: =IF(L19=1,IF(COUNTIFS(C$2:C19,C19,L$2:L19,1)=1,1,0),"") | T19: =IF(N19="","",N19+ROW()/10000000) | U19: =IF(G19=1,IF(B19="",1,0),"") -> 0
A20: 46083.134 | B20: 46083.134 | C20: FR02_TT01_H | D20: Chambre froide 2 - température haute | E20: Haute | F20: Froid | G20: =IF(A20="","",IF(AND(A20>=Debut,A20<Fin),1,0)) -> 1 | H20: =IF(G20=1,INT(ROUND((A20-Debut)*86400,0)/600),"") -> 19 | I20: =IF(G20=1,INT(ROUND((A20-Debut)*86400,0)/3600),"") -> 3 | J20: =IF(OR(A20="",B20=""),"",ROUND((B20-A20)*86400,0)) -> 6 | K20: =IF(G20=1,IF(COUNTIFS($C:$C,C20,$G:$G,1,$A:$A,">="&(A20-FenetreInterm/86400),$A:$A,"<="&A20)>=NbInterm,1,0),"") -> 1 | L20: =IF(G20=1,IF(B20="",0,IF(J20<SeuilFugitive,1,0)),"") -> 0 | M20: =IF(G20=1,IF(B20="",IF((Fin-A20)*24>SeuilFigee,1,0),IF(J20>SeuilFigee*3600,1,0)),"") -> 0 | N20: =IF(G20=1,IF(COUNTIF(H$2:H20,H20)=1,COUNTIF($H:$H,H20),""),"") | O20: =IF(G20=1,IF(COUNTIF(I$2:I20,I20)=1,COUNTIF($I:$I,I20),""),"") | P20: =IF(G20=1,IF(COUNTIFS(C$2:C20,C20,G$2:G20,1)=1,COUNTIFS($C:$C,C20,$G:$G,1)+ROW()/10000000,""),"") | Q20: =IF(K20=1,IF(COUNTIFS(C$2:C20,C20,K$2:K20,1)=1,1,0),"") -> 0 | R20: =IF(M20=1,IF(COUNTIFS(C$2:C20,C20,M$2:M20,1)=1,1,0),"") | S20: =IF(L20=1,IF(COUNTIFS(C$2:C20,C20,L$2:L20,1)=1,1,0),"") | T20: =IF(N20="","",N20+ROW()/10000000) | U20: =IF(G20=1,IF(B20="",1,0),"") -> 0
A21: 46083.134 | B21: 46083.134 | C21: FR02_TT01_H | D21: Chambre froide 2 - température haute | E21: Haute | F21: Froid | G21: =IF(A21="","",IF(AND(A21>=Debut,A21<Fin),1,0)) -> 1 | H21: =IF(G21=1,INT(ROUND((A21-Debut)*86400,0)/600),"") -> 19 | I21: =IF(G21=1,INT(ROUND((A21-Debut)*86400,0)/3600),"") -> 3 | J21: =IF(OR(A21="",B21=""),"",ROUND((B21-A21)*86400,0)) -> 21 | K21: =IF(G21=1,IF(COUNTIFS($C:$C,C21,$G:$G,1,$A:$A,">="&(A21-FenetreInterm/86400),$A:$A,"<="&A21)>=NbInterm,1,0),"") -> 1 | L21: =IF(G21=1,IF(B21="",0,IF(J21<SeuilFugitive,1,0)),"") -> 0 | M21: =IF(G21=1,IF(B21="",IF((Fin-A21)*24>SeuilFigee,1,0),IF(J21>SeuilFigee*3600,1,0)),"") -> 0 | N21: =IF(G21=1,IF(COUNTIF(H$2:H21,H21)=1,COUNTIF($H:$H,H21),""),"") | O21: =IF(G21=1,IF(COUNTIF(I$2:I21,I21)=1,COUNTIF($I:$I,I21),""),"") | P21: =IF(G21=1,IF(COUNTIFS(C$2:C21,C21,G$2:G21,1)=1,COUNTIFS($C:$C,C21,$G:$G,1)+ROW()/10000000,""),"") | Q21: =IF(K21=1,IF(COUNTIFS(C$2:C21,C21,K$2:K21,1)=1,1,0),"") -> 0 | R21: =IF(M21=1,IF(COUNTIFS(C$2:C21,C21,M$2:M21,1)=1,1,0),"") | S21: =IF(L21=1,IF(COUNTIFS(C$2:C21,C21,L$2:L21,1)=1,1,0),"") | T21: =IF(N21="","",N21+ROW()/10000000) | U21: =IF(G21=1,IF(B21="",1,0),"") -> 0
A22: 46083.134 | B22: 46083.134 | C22: FR02_TT01_H | D22: Chambre froide 2 - température haute | E22: Haute | F22: Froid | G22: =IF(A22="","",IF(AND(A22>=Debut,A22<Fin),1,0)) -> 1 | H22: =IF(G22=1,INT(ROUND((A22-Debut)*86400,0)/600),"") -> 19 | I22: =IF(G22=1,INT(ROUND((A22-Debut)*86400,0)/3600),"") -> 3 | J22: =IF(OR(A22="",B22=""),"",ROUND((B22-A22)*86400,0)) -> 18 | K22: =IF(G22=1,IF(COUNTIFS($C:$C,C22,$G:$G,1,$A:$A,">="&(A22-FenetreInterm/86400),$A:$A,"<="&A22)>=NbInterm,1,0),"") -> 1 | L22: =IF(G22=1,IF(B22="",0,IF(J22<SeuilFugitive,1,0)),"") -> 0 | M22: =IF(G22=1,IF(B22="",IF((Fin-A22)*24>SeuilFigee,1,0),IF(J22>SeuilFigee*3600,1,0)),"") -> 0 | N22: =IF(G22=1,IF(COUNTIF(H$2:H22,H22)=1,COUNTIF($H:$H,H22),""),"") | O22: =IF(G22=1,IF(COUNTIF(I$2:I22,I22)=1,COUNTIF($I:$I,I22),""),"") | P22: =IF(G22=1,IF(COUNTIFS(C$2:C22,C22,G$2:G22,1)=1,COUNTIFS($C:$C,C22,$G:$G,1)+ROW()/10000000,""),"") | Q22: =IF(K22=1,IF(COUNTIFS(C$2:C22,C22,K$2:K22,1)=1,1,0),"") -> 0 | R22: =IF(M22=1,IF(COUNTIFS(C$2:C22,C22,M$2:M22,1)=1,1,0),"") | S22: =IF(L22=1,IF(COUNTIFS(C$2:C22,C22,L$2:L22,1)=1,1,0),"") | T22: =IF(N22="","",N22+ROW()/10000000) | U22: =IF(G22=1,IF(B22="",1,0),"") -> 0
A23: 46083.138 | B23: 46083.138 | C23: FR02_TT01_H | D23: Chambre froide 2 - température haute | E23: Haute | F23: Froid | G23: =IF(A23="","",IF(AND(A23>=Debut,A23<Fin),1,0)) -> 1 | H23: =IF(G23=1,INT(ROUND((A23-Debut)*86400,0)/600),"") -> 19 | I23: =IF(G23=1,INT(ROUND((A23-Debut)*86400,0)/3600),"") -> 3 | J23: =IF(OR(A23="",B23=""),"",ROUND((B23-A23)*86400,0)) -> 23 | K23: =IF(G23=1,IF(COUNTIFS($C:$C,C23,$G:$G,1,$A:$A,">="&(A23-FenetreInterm/86400),$A:$A,"<="&A23)>=NbInterm,1,0),"") -> 0 | L23: =IF(G23=1,IF(B23="",0,IF(J23<SeuilFugitive,1,0)),"") -> 0 | M23: =IF(G23=1,IF(B23="",IF((Fin-A23)*24>SeuilFigee,1,0),IF(J23>SeuilFigee*3600,1,0)),"") -> 0 | N23: =IF(G23=1,IF(COUNTIF(H$2:H23,H23)=1,COUNTIF($H:$H,H23),""),"") | O23: =IF(G23=1,IF(COUNTIF(I$2:I23,I23)=1,COUNTIF($I:$I,I23),""),"") | P23: =IF(G23=1,IF(COUNTIFS(C$2:C23,C23,G$2:G23,1)=1,COUNTIFS($C:$C,C23,$G:$G,1)+ROW()/10000000,""),"") | Q23: =IF(K23=1,IF(COUNTIFS(C$2:C23,C23,K$2:K23,1)=1,1,0),"") | R23: =IF(M23=1,IF(COUNTIFS(C$2:C23,C23,M$2:M23,1)=1,1,0),"") | S23: =IF(L23=1,IF(COUNTIFS(C$2:C23,C23,L$2:L23,1)=1,1,0),"") | T23: =IF(N23="","",N23+ROW()/10000000) | U23: =IF(G23=1,IF(B23="",1,0),"") -> 0
A24: 46083.138 | B24: 46083.138 | C24: FR02_TT01_H | D24: Chambre froide 2 - température haute | E24: Haute | F24: Froid | G24: =IF(A24="","",IF(AND(A24>=Debut,A24<Fin),1,0)) -> 1 | H24: =IF(G24=1,INT(ROUND((A24-Debut)*86400,0)/600),"") -> 19 | I24: =IF(G24=1,INT(ROUND((A24-Debut)*86400,0)/3600),"") -> 3 | J24: =IF(OR(A24="",B24=""),"",ROUND((B24-A24)*86400,0)) -> 5 | K24: =IF(G24=1,IF(COUNTIFS($C:$C,C24,$G:$G,1,$A:$A,">="&(A24-FenetreInterm/86400),$A:$A,"<="&A24)>=NbInterm,1,0),"") -> 0 | L24: =IF(G24=1,IF(B24="",0,IF(J24<SeuilFugitive,1,0)),"") -> 0 | M24: =IF(G24=1,IF(B24="",IF((Fin-A24)*24>SeuilFigee,1,0),IF(J24>SeuilFigee*3600,1,0)),"") -> 0 | N24: =IF(G24=1,IF(COUNTIF(H$2:H24,H24)=1,COUNTIF($H:$H,H24),""),"") | O24: =IF(G24=1,IF(COUNTIF(I$2:I24,I24)=1,COUNTIF($I:$I,I24),""),"") | P24: =IF(G24=1,IF(COUNTIFS(C$2:C24,C24,G$2:G24,1)=1,COUNTIFS($C:$C,C24,$G:$G,1)+ROW()/10000000,""),"") | Q24: =IF(K24=1,IF(COUNTIFS(C$2:C24,C24,K$2:K24,1)=1,1,0),"") | R24: =IF(M24=1,IF(COUNTIFS(C$2:C24,C24,M$2:M24,1)=1,1,0),"") | S24: =IF(L24=1,IF(COUNTIFS(C$2:C24,C24,L$2:L24,1)=1,1,0),"") | T24: =IF(N24="","",N24+ROW()/10000000) | U24: =IF(G24=1,IF(B24="",1,0),"") -> 0
A25: 46083.138 | B25: 46083.139 | C25: FR02_TT01_H | D25: Chambre froide 2 - température haute | E25: Haute | F25: Froid | G25: =IF(A25="","",IF(AND(A25>=Debut,A25<Fin),1,0)) -> 1 | H25: =IF(G25=1,INT(ROUND((A25-Debut)*86400,0)/600),"") -> 19 | I25: =IF(G25=1,INT(ROUND((A25-Debut)*86400,0)/3600),"") -> 3 | J25: =IF(OR(A25="",B25=""),"",ROUND((B25-A25)*86400,0)) -> 8 | K25: =IF(G25=1,IF(COUNTIFS($C:$C,C25,$G:$G,1,$A:$A,">="&(A25-FenetreInterm/86400),$A:$A,"<="&A25)>=NbInterm,1,0),"") -> 1 | L25: =IF(G25=1,IF(B25="",0,IF(J25<SeuilFugitive,1,0)),"") -> 0 | M25: =IF(G25=1,IF(B25="",IF((Fin-A25)*24>SeuilFigee,1,0),IF(J25>SeuilFigee*3600,1,0)),"") -> 0 | N25: =IF(G25=1,IF(COUNTIF(H$2:H25,H25)=1,COUNTIF($H:$H,H25),""),"") | O25: =IF(G25=1,IF(COUNTIF(I$2:I25,I25)=1,COUNTIF($I:$I,I25),""),"") | P25: =IF(G25=1,IF(COUNTIFS(C$2:C25,C25,G$2:G25,1)=1,COUNTIFS($C:$C,C25,$G:$G,1)+ROW()/10000000,""),"") | Q25: =IF(K25=1,IF(COUNTIFS(C$2:C25,C25,K$2:K25,1)=1,1,0),"") -> 0 | R25: =IF(M25=1,IF(COUNTIFS(C$2:C25,C25,M$2:M25,1)=1,1,0),"") | S25: =IF(L25=1,IF(COUNTIFS(C$2:C25,C25,L$2:L25,1)=1,1,0),"") | T25: =IF(N25="","",N25+ROW()/10000000) | U25: =IF(G25=1,IF(B25="",1,0),"") -> 0
A26: 46083.139 | B26: 46083.139 | C26: FR02_TT01_H | D26: Chambre froide 2 - température haute | E26: Haute | F26: Froid | G26: =IF(A26="","",IF(AND(A26>=Debut,A26<Fin),1,0)) -> 1 | H26: =IF(G26=1,INT(ROUND((A26-Debut)*86400,0)/600),"") -> 19 | I26: =IF(G26=1,INT(ROUND((A26-Debut)*86400,0)/3600),"") -> 3 | J26: =IF(OR(A26="",B26=""),"",ROUND((B26-A26)*86400,0)) -> 7 | K26: =IF(G26=1,IF(COUNTIFS($C:$C,C26,$G:$G,1,$A:$A,">="&(A26-FenetreInterm/86400),$A:$A,"<="&A26)>=NbInterm,1,0),"") -> 1 | L26: =IF(G26=1,IF(B26="",0,IF(J26<SeuilFugitive,1,0)),"") -> 0 | M26: =IF(G26=1,IF(B26="",IF((Fin-A26)*24>SeuilFigee,1,0),IF(J26>SeuilFigee*3600,1,0)),"") -> 0 | N26: =IF(G26=1,IF(COUNTIF(H$2:H26,H26)=1,COUNTIF($H:$H,H26),""),"") | O26: =IF(G26=1,IF(COUNTIF(I$2:I26,I26)=1,COUNTIF($I:$I,I26),""),"") | P26: =IF(G26=1,IF(COUNTIFS(C$2:C26,C26,G$2:G26,1)=1,COUNTIFS($C:$C,C26,$G:$G,1)+ROW()/10000000,""),"") | Q26: =IF(K26=1,IF(COUNTIFS(C$2:C26,C26,K$2:K26,1)=1,1,0),"") -> 0 | R26: =IF(M26=1,IF(COUNTIFS(C$2:C26,C26,M$2:M26,1)=1,1,0),"") | S26: =IF(L26=1,IF(COUNTIFS(C$2:C26,C26,L$2:L26,1)=1,1,0),"") | T26: =IF(N26="","",N26+ROW()/10000000) | U26: =IF(G26=1,IF(B26="",1,0),"") -> 0
A27: 46083.155 | B27: 46083.155 | C27: FR02_TT01_H | D27: Chambre froide 2 - température haute | E27: Haute | F27: Froid | G27: =IF(A27="","",IF(AND(A27>=Debut,A27<Fin),1,0)) -> 1 | H27: =IF(G27=1,INT(ROUND((A27-Debut)*86400,0)/600),"") -> 22 | I27: =IF(G27=1,INT(ROUND((A27-Debut)*86400,0)/3600),"") -> 3 | J27: =IF(OR(A27="",B27=""),"",ROUND((B27-A27)*86400,0)) -> 13 | K27: =IF(G27=1,IF(COUNTIFS($C:$C,C27,$G:$G,1,$A:$A,">="&(A27-FenetreInterm/86400),$A:$A,"<="&A27)>=NbInterm,1,0),"") -> 0 | L27: =IF(G27=1,IF(B27="",0,IF(J27<SeuilFugitive,1,0)),"") -> 0 | M27: =IF(G27=1,IF(B27="",IF((Fin-A27)*24>SeuilFigee,1,0),IF(J27>SeuilFigee*3600,1,0)),"") -> 0 | N27: =IF(G27=1,IF(COUNTIF(H$2:H27,H27)=1,COUNTIF($H:$H,H27),""),"") -> 7 | O27: =IF(G27=1,IF(COUNTIF(I$2:I27,I27)=1,COUNTIF($I:$I,I27),""),"") | P27: =IF(G27=1,IF(COUNTIFS(C$2:C27,C27,G$2:G27,1)=1,COUNTIFS($C:$C,C27,$G:$G,1)+ROW()/10000000,""),"") | Q27: =IF(K27=1,IF(COUNTIFS(C$2:C27,C27,K$2:K27,1)=1,1,0),"") | R27: =IF(M27=1,IF(COUNTIFS(C$2:C27,C27,M$2:M27,1)=1,1,0),"") | S27: =IF(L27=1,IF(COUNTIFS(C$2:C27,C27,L$2:L27,1)=1,1,0),"") | T27: =IF(N27="","",N27+ROW()/10000000) -> 7.0000027 | U27: =IF(G27=1,IF(B27="",1,0),"") -> 0
A28: 46083.155 | B28: 46083.155 | C28: FR02_TT01_H | D28: Chambre froide 2 - température haute | E28: Haute | F28: Froid | G28: =IF(A28="","",IF(AND(A28>=Debut,A28<Fin),1,0)) -> 1 | H28: =IF(G28=1,INT(ROUND((A28-Debut)*86400,0)/600),"") -> 22 | I28: =IF(G28=1,INT(ROUND((A28-Debut)*86400,0)/3600),"") -> 3 | J28: =IF(OR(A28="",B28=""),"",ROUND((B28-A28)*86400,0)) -> 17 | K28: =IF(G28=1,IF(COUNTIFS($C:$C,C28,$G:$G,1,$A:$A,">="&(A28-FenetreInterm/86400),$A:$A,"<="&A28)>=NbInterm,1,0),"") -> 0 | L28: =IF(G28=1,IF(B28="",0,IF(J28<SeuilFugitive,1,0)),"") -> 0 | M28: =IF(G28=1,IF(B28="",IF((Fin-A28)*24>SeuilFigee,1,0),IF(J28>SeuilFigee*3600,1,0)),"") -> 0 | N28: =IF(G28=1,IF(COUNTIF(H$2:H28,H28)=1,COUNTIF($H:$H,H28),""),"") | O28: =IF(G28=1,IF(COUNTIF(I$2:I28,I28)=1,COUNTIF($I:$I,I28),""),"") | P28: =IF(G28=1,IF(COUNTIFS(C$2:C28,C28,G$2:G28,1)=1,COUNTIFS($C:$C,C28,$G:$G,1)+ROW()/10000000,""),"") | Q28: =IF(K28=1,IF(COUNTIFS(C$2:C28,C28,K$2:K28,1)=1,1,0),"") | R28: =IF(M28=1,IF(COUNTIFS(C$2:C28,C28,M$2:M28,1)=1,1,0),"") | S28: =IF(L28=1,IF(COUNTIFS(C$2:C28,C28,L$2:L28,1)=1,1,0),"") | T28: =IF(N28="","",N28+ROW()/10000000) | U28: =IF(G28=1,IF(B28="",1,0),"") -> 0
A29: 46083.155 | B29: 46083.155 | C29: FR02_TT01_H | D29: Chambre froide 2 - température haute | E29: Haute | F29: Froid | G29: =IF(A29="","",IF(AND(A29>=Debut,A29<Fin),1,0)) -> 1 | H29: =IF(G29=1,INT(ROUND((A29-Debut)*86400,0)/600),"") -> 22 | I29: =IF(G29=1,INT(ROUND((A29-Debut)*86400,0)/3600),"") -> 3 | J29: =IF(OR(A29="",B29=""),"",ROUND((B29-A29)*86400,0)) -> 24 | K29: =IF(G29=1,IF(COUNTIFS($C:$C,C29,$G:$G,1,$A:$A,">="&(A29-FenetreInterm/86400),$A:$A,"<="&A29)>=NbInterm,1,0),"") -> 1 | L29: =IF(G29=1,IF(B29="",0,IF(J29<SeuilFugitive,1,0)),"") -> 0 | M29: =IF(G29=1,IF(B29="",IF((Fin-A29)*24>SeuilFigee,1,0),IF(J29>SeuilFigee*3600,1,0)),"") -> 0 | N29: =IF(G29=1,IF(COUNTIF(H$2:H29,H29)=1,COUNTIF($H:$H,H29),""),"") | O29: =IF(G29=1,IF(COUNTIF(I$2:I29,I29)=1,COUNTIF($I:$I,I29),""),"") | P29: =IF(G29=1,IF(COUNTIFS(C$2:C29,C29,G$2:G29,1)=1,COUNTIFS($C:$C,C29,$G:$G,1)+ROW()/10000000,""),"") | Q29: =IF(K29=1,IF(COUNTIFS(C$2:C29,C29,K$2:K29,1)=1,1,0),"") -> 0 | R29: =IF(M29=1,IF(COUNTIFS(C$2:C29,C29,M$2:M29,1)=1,1,0),"") | S29: =IF(L29=1,IF(COUNTIFS(C$2:C29,C29,L$2:L29,1)=1,1,0),"") | T29: =IF(N29="","",N29+ROW()/10000000) | U29: =IF(G29=1,IF(B29="",1,0),"") -> 0
A30: 46083.155 | B30: 46083.155 | C30: FR02_TT01_H | D30: Chambre froide 2 - température haute | E30: Haute | F30: Froid | G30: =IF(A30="","",IF(AND(A30>=Debut,A30<Fin),1,0)) -> 1 | H30: =IF(G30=1,INT(ROUND((A30-Debut)*86400,0)/600),"") -> 22 | I30: =IF(G30=1,INT(ROUND((A30-Debut)*86400,0)/3600),"") -> 3 | J30: =IF(OR(A30="",B30=""),"",ROUND((B30-A30)*86400,0)) -> 8 | K30: =IF(G30=1,IF(COUNTIFS($C:$C,C30,$G:$G,1,$A:$A,">="&(A30-FenetreInterm/86400),$A:$A,"<="&A30)>=NbInterm,1,0),"") -> 1 | L30: =IF(G30=1,IF(B30="",0,IF(J30<SeuilFugitive,1,0)),"") -> 0 | M30: =IF(G30=1,IF(B30="",IF((Fin-A30)*24>SeuilFigee,1,0),IF(J30>SeuilFigee*3600,1,0)),"") -> 0 | N30: =IF(G30=1,IF(COUNTIF(H$2:H30,H30)=1,COUNTIF($H:$H,H30),""),"") | O30: =IF(G30=1,IF(COUNTIF(I$2:I30,I30)=1,COUNTIF($I:$I,I30),""),"") | P30: =IF(G30=1,IF(COUNTIFS(C$2:C30,C30,G$2:G30,1)=1,COUNTIFS($C:$C,C30,$G:$G,1)+ROW()/10000000,""),"") | Q30: =IF(K30=1,IF(COUNTIFS(C$2:C30,C30,K$2:K30,1)=1,1,0),"") -> 0 | R30: =IF(M30=1,IF(COUNTIFS(C$2:C30,C30,M$2:M30,1)=1,1,0),"") | S30: =IF(L30=1,IF(COUNTIFS(C$2:C30,C30,L$2:L30,1)=1,1,0),"") | T30: =IF(N30="","",N30+ROW()/10000000) | U30: =IF(G30=1,IF(B30="",1,0),"") -> 0
... A1337: 46089.956 | B1337: 46089.957 | C1337: FR02_TT01_H | D1337: Chambre froide 2 - température haute | E1337: Haute | F1337: Froid | G1337: =IF(A1337="","",IF(AND(A1337>=Debut,A1337<Fin),1,0)) -> 1 | H1337: =IF(G1337=1,INT(ROUND((A1337-Debut)*86400,0)/600),"") -> 1001 | I1337: =IF(G1337=1,INT(ROUND((A1337-Debut)*86400,0)/3600),"") -> 166 | J1337: =IF(OR(A1337="",B1337=""),"",ROUND((B1337-A1337)*86400,0)) -> 11 | K1337: =IF(G1337=1,IF(COUNTIFS($C:$C,C1337,$G:$G,1,$A:$A,">="&(A1337-FenetreInterm/86400),$A:$A,"<="&A1337)>=NbInterm,1,0),"") -> 1 | L1337: =IF(G1337=1,IF(B1337="",0,IF(J1337<SeuilFugitive,1,0)),"") -> 0 | M1337: =IF(G1337=1,IF(B1337="",IF((Fin-A1337)*24>SeuilFigee,1,0),IF(J1337>SeuilFigee*3600,1,0)),"") -> 0 | N1337: =IF(G1337=1,IF(COUNTIF(H$2:H1337,H1337)=1,COUNTIF($H:$H,H1337),""),"") | O1337: =IF(G1337=1,IF(COUNTIF(I$2:I1337,I1337)=1,COUNTIF($I:$I,I1337),""),"") | P1337: =IF(G1337=1,IF(COUNTIFS(C$2:C1337,C1337,G$2:G1337,1)=1,COUNTIFS($C:$C,C1337,$G:$G,1)+ROW()/10000000,""),"") | Q1337: =IF(K1337=1,IF(COUNTIFS(C$2:C1337,C1337,K$2:K1337,1)=1,1,0),"") -> 0 | R1337: =IF(M1337=1,IF(COUNTIFS(C$2:C1337,C1337,M$2:M1337,1)=1,1,0),"") | S1337: =IF(L1337=1,IF(COUNTIFS(C$2:C1337,C1337,L$2:L1337,1)=1,1,0),"") | T1337: =IF(N1337="","",N1337+ROW()/10000000) | U1337: =IF(G1337=1,IF(B1337="",1,0),"") -> 0
